<?xml version="1.0" encoding="UTF-8"?>
<testng-results skipped="0" failed="1" total="2" passed="1">
  <reporter-output>
  </reporter-output>
  <suite name="Suite" duration-ms="75" started-at="2016-10-10T06:15:30Z" finished-at="2016-10-10T06:15:30Z">
    <groups>
    </groups>
    <test name="Test" duration-ms="75" started-at="2016-10-10T06:15:30Z" finished-at="2016-10-10T06:15:30Z">
      <class name="pkgTest.NewTest">
        <test-method status="FAIL" signature="testFail()[pri:0, instance:pkgTest.NewTest@ba2a48]" name="testFail" duration-ms="32" started-at="2016-10-10T11:45:30Z" finished-at="2016-10-10T11:45:30Z">
          <exception class="java.lang.AssertionError">
            <message>
              <![CDATA[expected [This test case if failed.] but found [This test case is failed]]]>
            </message>
            <full-stacktrace>
              <![CDATA[java.lang.AssertionError: expected [This test case if failed.] but found [This test case is failed]
	at org.testng.Assert.fail(Assert.java:89)
	at org.testng.Assert.failNotEquals(Assert.java:489)
	at org.testng.Assert.assertEquals(Assert.java:118)
	at org.testng.Assert.assertEquals(Assert.java:171)
	at org.testng.Assert.assertEquals(Assert.java:181)
	at pkgTest.NewTest.testFail(NewTest.java:17)
	at sun.reflect.NativeMethodAccessorImpl.invoke0(Native Method)
	at sun.reflect.NativeMethodAccessorImpl.invoke(Unknown Source)
	at sun.reflect.DelegatingMethodAccessorImpl.invoke(Unknown Source)
	at java.lang.reflect.Method.invoke(Unknown Source)
	at org.testng.internal.MethodInvocationHelper.invokeMethod(MethodInvocationHelper.java:80)
	at org.testng.internal.Invoker.invokeMethod(Invoker.java:715)
	at org.testng.internal.Invoker.invokeTestMethod(Invoker.java:907)
	at org.testng.internal.Invoker.invokeTestMethods(Invoker.java:1237)
	at org.testng.internal.TestMethodWorker.invokeTestMethods(TestMethodWorker.java:127)
	at org.testng.internal.TestMethodWorker.run(TestMethodWorker.java:111)
	at org.testng.TestRunner.privateRun(TestRunner.java:767)
	at org.testng.TestRunner.run(TestRunner.java:617)
	at org.testng.SuiteRunner.runTest(SuiteRunner.java:334)
	at org.testng.SuiteRunner.runSequentially(SuiteRunner.java:329)
	at org.testng.SuiteRunner.privateRun(SuiteRunner.java:291)
	at org.testng.SuiteRunner.run(SuiteRunner.java:240)
	at org.testng.SuiteRunnerWorker.runSuite(SuiteRunnerWorker.java:51)
	at org.testng.SuiteRunnerWorker.run(SuiteRunnerWorker.java:85)
	at org.testng.TestNG.runSuitesSequentially(TestNG.java:1197)
	at org.testng.TestNG.runSuitesLocally(TestNG.java:1122)
	at org.testng.TestNG.run(TestNG.java:1030)
	at org.testng.remote.AbstractRemoteTestNG.run(AbstractRemoteTestNG.java:132)
	at org.testng.remote.RemoteTestNG.initAndRun(RemoteTestNG.java:236)
	at org.testng.remote.RemoteTestNG.main(RemoteTestNG.java:81)
]]>
            </full-stacktrace>
          </exception> <!-- java.lang.AssertionError -->
          <reporter-output>
          </reporter-output>
        </test-method> <!-- testFail -->
        <test-method status="PASS" signature="testPass()[pri:0, instance:pkgTest.NewTest@ba2a48]" name="testPass" duration-ms="5" started-at="2016-10-10T11:45:30Z" finished-at="2016-10-10T11:45:30Z">
          <reporter-output>
          </reporter-output>
        </test-method> <!-- testPass -->
      </class> <!-- pkgTest.NewTest -->
    </test> <!-- Test -->
  </suite> <!-- Suite -->
</testng-results>
